<?xml version="1.0"?>
<robot name="tortoisebot">

  <link name="base_link">
    <visual>
      <geometry>
        <box size="0.6 0.3 0.1"/>
      </geometry>
      <material name="silver">
        <color rgba="0.75 0.75 0.75 1"/>
      </material>
      <origin rpy="0 0 0" xyz="0 0 -0.1"/>
    </visual>
    <collision>
      <geometry>
        <box size="0.6 0.3 0.1"/>
      </geometry>
    </collision>
    <inertial>
      <mass value="0.33"/>
      <inertia ixx="0.00270" iyy="0.0101" izz="0.0123" ixy="0" ixz="0" iyz="0"/>
    </inertial>
  </link>
    <gazebo reference="base_link">
        <material>Gazebo/Yellow</material>
    </gazebo> 

  <link name="front_caster">
    <visual>
      <geometry>
        <box size="0.1 0.1 0.1"/>
      </geometry>
      <material name="silver"/>
      <origin rpy="0 0 0" xyz="0 0 -0.11"/>
    </visual>
    <collision>
      <geometry>
        <box size="0.1 0.1 0.1"/>
      </geometry>
    </collision>
    <inertial>
      <mass value="0.1"/><!--wh,dh,dw-->
      <inertia ixx="0.0001" iyy="0.0001" izz="0.0001" ixy="0" ixz="0" iyz="0"/>
    </inertial>
  </link>
    <gazebo reference="front_caster">
        <material>Gazebo/Black</material>
    </gazebo> 

  <joint name="front_caster_joint" type="continuous">
    <axis xyz="0 0 1"/>
    <parent link="base_link"/>
    <child link="front_caster"/>
    <origin rpy="0 0 0" xyz="0.2 0 0"/>
  </joint>

  <link name="front_wheel">
    <visual>
      <geometry>
        <cylinder length="0.05" radius="0.035"/>
      </geometry>
      <material name="black"/>
    </visual>
    <collision>
      <geometry>
        <cylinder length="0.05" radius="0.035"/>
      </geometry>
    </collision>
    <inertial>
      <mass value="0.1"/>
      <inertia ixx="5.1458e-5" iyy="5.1458e-5" izz="6.125e-5" ixy="0" ixz="0" iyz="0"/>
    </inertial>
  </link>
    <gazebo reference="front_wheel">
        <material>Gazebo/Red</material>
    </gazebo> 

  <joint name="front_wheel_joint" type="continuous">
    <axis xyz="0 0 1"/>
    <parent link="front_caster"/>
    <child link="front_wheel"/>
    <origin rpy="-1.5708 0 0" xyz="0.05 0 -.15"/>
  </joint>

  <link name="right_wheel">
    <visual>
      <geometry>
        <cylinder length="0.05" radius="0.035"/>
      </geometry>
      <material name="black">
        <color rgba="0 0 0 1"/>
      </material>
    </visual>
    <collision>
      <geometry>
        <cylinder length="0.05" radius="0.035"/>
      </geometry>
    </collision>
    <inertial>
      <mass value="0.1"/>
      <inertia ixx="5.1458e-5" iyy="5.1458e-5" izz="6.125e-5" ixy="0" ixz="0" iyz="0"/>
    </inertial>
  </link>
    <gazebo reference="right_wheel">
        <material>Gazebo/Black</material>
    </gazebo> 

  <joint name="right_wheel_joint" type="continuous">
    <axis xyz="0 0 1"/>
    <parent link="base_link"/>
    <child link="right_wheel"/>
    <origin rpy="-1.5708 0 0" xyz="-0.2825 -0.13 -.15"/>
  </joint>

  <link name="left_wheel">
    <visual>
      <geometry>
        <cylinder length="0.05" radius="0.035"/>
      </geometry>
      <material name="black"/>
    </visual>
    <collision>
      <geometry>
        <cylinder length="0.05" radius="0.035"/>
      </geometry>
    </collision>
    <inertial>
      <mass value="0.1"/>
      <inertia ixx="5.1458e-5" iyy="5.1458e-5" izz="6.125e-5" ixy="0" ixz="0" iyz="0"/>
    </inertial>
  </link>
    <gazebo reference="left_wheel">
        <material>Gazebo/Black</material>
    </gazebo> 

  <joint name="left_wheel_joint" type="continuous">
    <axis xyz="0 0 1"/>
    <parent link="base_link"/>
    <child link="left_wheel"/>
    <origin rpy="-1.5708 0 0" xyz="-0.2825 0.13 -.15"/>
  </joint>

  <link name="camera_link">
    <collision>
      <origin xyz="0 0 0" rpy="0 0 0"/>
      <geometry>
        <box size="0.1 0.1 0.1"/>
      </geometry>
    </collision>
    <visual>
      <origin xyz="0 0 0" rpy="0 0.4 0"/>
      <geometry>
        <box size="0.1 0.1 0.1"/>
      </geometry>
    </visual>
    <inertial>
      <mass value="1e-5" />
      <origin xyz="0 0 0" rpy="0 0 0"/>
      <inertia ixx="1e-6" ixy="0" ixz="0" iyy="1e-6" iyz="0" izz="1e-6" />
    </inertial>
  </link>
    <gazebo reference="camera_link">
        <material>Gazebo/Blue</material>
    </gazebo> 

  <joint name="camera_joint" type="fixed">
    <axis xyz="0 1 0" />
    <origin xyz="0.3 0 0" rpy="0 0.2 0"/>
    <parent link="base_link"/>
    <child link="camera_link"/>
  </joint>

  <gazebo>
    <plugin name="differential_drive_controller" filename="libgazebo_ros_diff_drive.so">
      <leftJoint>right_wheel_joint</leftJoint>
      <rightJoint>left_wheel_joint</rightJoint>
      <robotBaseFrame>base_link</robotBaseFrame>
      <wheelSeparation>0.26</wheelSeparation>
      <wheelDiameter>0.07</wheelDiameter>
      <legacyMode>true</legacyMode>
      <publishWheelJointState>true</publishWheelJointState>
    </plugin>
  </gazebo>

  <gazebo>
    <plugin name="joint_state_publisher" filename="libgazebo_ros_joint_state_publisher.so">
      <jointName>front_caster_joint, front_wheel_joint</jointName>
    </plugin>
  </gazebo>

  <gazebo reference="camera_link">
	<sensor type="camera" name="camera_node">
		<pose>0 0 0 0 0 0</pose>
                <update_rate>60.0</update_rate>
                <camera name="head">
                    <horizontal_fov>1.3962634</horizontal_fov>
                    <image>
                        <width>1280</width>
                        <height>720</height>
                        <format>R8G8B8</format>
                    </image>
                    <clip>
                        <near>0.02</near>
                        <far>300</far>
                    </clip>
                    <noise>
                        <type>gaussian</type>
                        <mean>0.0</mean>
                        <stddev>0.007</stddev>
                    </noise>
                </camera>
                <plugin name="gazebo_camera" filename="libgazebo_ros_camera.so">
                    <alwaysOn>true</alwaysOn>
                    <updateRate>0.0</updateRate>
                    <cameraName>/camera</cameraName>
                    <imageTopicName>image_raw</imageTopicName>
                    <cameraInfoTopicName>camera_info</cameraInfoTopicName>
                    <frameName>camera_link</frameName>
                    <hackBaseline>0.07</hackBaseline>
                    <distortionK1>0.0</distortionK1>
                    <distortionK2>0.0</distortionK2>
                    <distortionK3>0.0</distortionK3>
                    <distortionT1>0.0</distortionT1>
                    <distortionT2>0.0</distortionT2>
                </plugin>
            </sensor>
  </gazebo>
</robot>
