<?xml version="1.0"?>
<robot>

  <property name="left_leg_gripper_j0_damping" value= "1.0" />
  <property name="left_leg_gripper_j0_friction" value= "0.0" />
  <property name="left_leg_gripper_j1_damping" value= "1.0" />
  <property name="left_leg_gripper_j1_friction" value= "0.0" />
  <property name="left_leg_gripper_j1_damping" value= "1.0" />
  <property name="left_leg_gripper_j1_friction" value= "0.0" />

  <joint name="${robot_name}fixed/left_ankle_roll/left_leg_foot" type="fixed">
    <parent link="${robot_name}left_ankle_roll"/>
    <child link="${robot_name}left_leg_foot"/>
    <origin rpy="0.0 0 0" xyz="0.0 0.0 0.04953"/>
  </joint>

  <link name="${robot_name}left_leg_foot">
    <inertial>
      <mass value="4.40475"/>
      <inertia ixx="0.1" ixy="0.0" ixz="0.0" iyy="0.1" iyz="0.0" izz="0.1"/>
    </inertial>
    <visual>
      <geometry>
        <mesh filename="package://r2_description/meshes/r2_legs/r2cl_foot.dae"/>
      </geometry>
      <origin xyz="0 0 0" rpy="0 0 0" />
    </visual>
    <collision>
      <geometry>
        <mesh filename="package://r2_description/meshes/r2_legs/r2cl_foot.dae"/>
      </geometry>
      <origin rpy="0 0 0" xyz="0 0 0"/>
    </collision>
  </link>

  <joint name="${robot_name}fixed/left_foot/simulated_camboard" type="fixed">
    <parent link="${robot_name}left_leg_foot"/>
    <child link="${robot_name}simulated_left_foot_camboard_frame"/>
    <dynamics damping="1.0" />
    <origin rpy="0 -1.57 -1.57" xyz="0.015 0.07 .165"/>
  </joint>

  <joint name="${robot_name}fixed/left_foot/simulated_camboard_depth" type="fixed">
    <parent link="${robot_name}left_leg_foot"/>
    <child link="${robot_name}simulated_left_foot_camboard_depth_frame"/>
    <dynamics damping="1.0" />
    <origin rpy="3.14 3.14 0" xyz="0.015 0.07 .165"/>
  </joint>


<!--  placeholder for screw joint-->
  <joint name="${robot_name}left_leg/gripper/joint0" type="revolute">
    <parent link="${robot_name}left_leg_foot"/>
    <child link="${robot_name}left_leg/gripper/link0"/>
    <origin rpy="0.0 0 0" xyz="0 0 0"/>
    <axis xyz="0 0 1"/>
    <dynamics damping="${left_leg_gripper_j0_damping}" friction="${left_leg_gripper_j0_friction}"/>
    <limit effort="330.0" lower="-.5" upper=".5" velocity="1.0"/>
  </joint>

  <joint name="${robot_name}left_leg/gripper/joint1" type="revolute">
    <parent link="${robot_name}left_leg_foot"/>
    <child link="${robot_name}left_leg_jaw0"/>
    <origin rpy="0.0 0 0" xyz="0.01905 0 0.17546"/>
    <axis xyz="0 -1 0"/>
    <dynamics damping="${left_leg_gripper_j0_damping}" friction="${left_leg_gripper_j0_friction}"/>
    <limit effort="330.0" lower="-.5" upper=".5" velocity="1.0"/>
  </joint>

  <joint name="${robot_name}left_leg/gripper/joint2" type="revolute">
    <parent link="${robot_name}left_leg_foot"/>
    <child link="${robot_name}left_leg_jaw1"/>
    <origin rpy="0.0 0 0" xyz="-0.01905 0 0.17546"/>
    <axis xyz="0 1 0"/>
    <dynamics damping="${left_leg_gripper_j1_damping}" friction="${left_leg_gripper_j1_friction}"/>
    <limit effort="330.0" lower="-.5" upper=".5" velocity="1.0"/>
  </joint>

  <joint name="${robot_name}fixed/left_leg_foot/left_hr_tip" type="fixed">
    <parent link="${robot_name}left_leg_foot"/>
    <child link="${robot_name}left_hr_tip"/>
    <origin rpy="0.0 0 0" xyz="0 0 0.19451"/>
  </joint>

  <joint name="${robot_name}fixed/left_leg_foot/left_st_tip" type="fixed">
    <parent link="${robot_name}left_leg_foot"/>
    <child link="${robot_name}left_st_tip"/>
    <origin rpy="0.0 0 0" xyz="0 0 0.21991"/>
  </joint>

  <joint name="${robot_name}fixed/left_leg_foot/left_leg_camera0_physical" type="fixed">
    <parent link="${robot_name}left_leg_foot"/>
    <child link="${robot_name}left_leg_camera0_physical"/>
    <origin rpy="0 0 0" xyz="-0.025 .07 0.13"/>
  </joint>

  <joint name="${robot_name}fixed/left_leg_foot/left_leg_camera1_physical" type="fixed">
    <parent link="${robot_name}left_leg_foot"/>
    <child link="${robot_name}left_leg_camera1_physical"/>
    <origin rpy="0.0 0 0" xyz="0.025 .07 0.13"/>
  </joint>

<!--  placeholder for screw-->
  <non_visual_link name="${robot_name}left_leg/gripper/link0"/>

  <non_visual_link name="${robot_name}left_hr_tip"/>

  <non_visual_link name="${robot_name}left_st_tip"/>

 <!-- simulated camboard -->
  <link name="${robot_name}simulated_left_foot_camboard_frame">
    <inertial>
      <mass value=".1"/>
      <inertia ixx=".01" ixy="0.0" ixz="0.0" iyy=".01" iyz="0.0" izz=".01"/>
    </inertial>
  </link>

  <!-- simulated camboard -->
  <link name="${robot_name}simulated_left_foot_camboard_depth_frame">
    <inertial>
      <mass value=".1"/>
      <inertia ixx=".01" ixy="0.0" ixz="0.0" iyy=".01" iyz="0.0" izz=".01"/>
    </inertial>
  </link>


  <link name="${robot_name}left_leg_jaw0">
    <inertial>
      <mass value="0.16268"/>
      <inertia ixx="0.1" ixy="0.0" ixz="0.0" iyy="0.1" iyz="0.0" izz="0.1"/>
    </inertial>
    <visual>
      <geometry>
        <mesh filename="package://r2_description/meshes/r2_legs/r2cl_foot_jaw1.dae"/>
      </geometry>
      <origin rpy="0 0 0" xyz="0 0 0"/>
    </visual>
    <collision>
      <geometry>
        <mesh filename="package://r2_description/meshes/r2_legs/r2cl_foot_jaw1.dae"/>
      </geometry>
      <origin rpy="0 0 0" xyz="0 0 0"/>
    </collision>
  </link>

  <link name="${robot_name}left_leg_jaw1">
    <inertial>
      <mass value="0.16268"/>
      <inertia ixx="0.1" ixy="0.0" ixz="0.0" iyy="0.1" iyz="0.0" izz="0.1"/>
    </inertial>
    <visual>
      <geometry>
        <mesh filename="package://r2_description/meshes/r2_legs/r2cl_foot_jaw2.dae"/>
      </geometry>
      <origin rpy="0 0 0" xyz="0 0 0"/>
    </visual>
    <collision>
      <geometry>
        <mesh filename="package://r2_description/meshes/r2_legs/r2cl_foot_jaw2.dae"/>
      </geometry>
      <origin rpy="0 0 0" xyz="0 0 0"/>
    </collision>
  </link>

  <non_visual_link name="${robot_name}left_leg_camera0_physical"/>

  <joint name="${robot_name}fixed/left_leg_camera0_physical/left_leg_camera0_optical" type="fixed">
    <parent link="${robot_name}left_leg_camera0_physical"/>
    <child link="${robot_name}left_leg_camera0_optical"/>
    <origin rpy="0 -1.57 -1.57" xyz="0 0 .03"/>
  </joint>

  <non_visual_link name="${robot_name}left_leg_camera0_optical"/>

  <non_visual_link name="${robot_name}left_leg_camera1_physical"/>

  <joint name="${robot_name}fixed/left_leg_camera1_physical/left_leg_camera1_optical" type="fixed">
    <parent link="${robot_name}left_leg_camera1_physical"/>
    <child link="${robot_name}left_leg_camera1_optical"/>
    <origin rpy="0 -1.57 -1.57" xyz="0 0 0.03"/>
  </joint>

  <non_visual_link name="${robot_name}left_leg_camera1_optical"/>

</robot>
