<?xml version="1.0"?>
<robot>

  <property name="right_leg_j0_damping" value= "10.0" />
  <property name="right_leg_j0_friction" value= "0.0" />
  <property name="right_leg_j1_damping" value= "5.0" />
  <property name="right_leg_j1_friction" value= "0.0" />
  <property name="right_leg_j2_damping" value= "5.0" />
  <property name="right_leg_j2_friction" value= "0.0" />
  <property name="right_leg_j3_damping" value= "5.0" />
  <property name="right_leg_j3_friction" value= "0.0" />
  <property name="right_leg_j4_damping" value= "5.0" />
  <property name="right_leg_j4_friction" value= "0.0" />
  <property name="right_leg_j5_damping" value= "5.0" />
  <property name="right_leg_j5_friction" value= "0.0" />
  <property name="right_leg_j6_damping" value= "5.0" />
  <property name="right_leg_j6_friction" value= "0.0" />

  <joint name="${robot_name}fixed/pelvis/right_leg_base" type="fixed">
    <parent link="${robot_name}pelvis"/>
    <child link="${robot_name}right_leg_base"/>
    <origin rpy="0 0.000000 1.570796" xyz="0.0 0 0.0"/>
  </joint>

  <link name="${robot_name}right_leg_base">
    <inertial>
      <mass value="3.2"/>
      <inertia ixx="1.0" ixy="0.0" ixz="0.0" iyy="1.0" iyz="0.0" izz="1.0"/>
    </inertial>
    <visual>
      <geometry>
        <cylinder length=".11" radius=".05"/>
      </geometry>
      <origin rpy="0 1.82 0" xyz="0.055 0.0 -.015 "/>
    </visual>
    <collision>
      <geometry>
        <cylinder length=".11" radius=".05"/>
      </geometry>
      <origin rpy="0 1.82 0" xyz="0.055 0.0 -.015 "/>
    </collision>
  </link>

  <joint name="${robot_name}fixed/right_leg_base/right_leg_j0_base" type="fixed">
    <parent link="${robot_name}right_leg_base"/>
    <child link="${robot_name}right_leg_j0_base"/>
    <origin rpy="0.0 1.8325957 0" xyz="0.1104900 0.0 -0.0297180"/>
  </joint>

  <non_visual_link name="${robot_name}right_leg_j0_base"/>

  <joint name="${robot_name}right_leg/joint0" type="revolute">
    <parent link="${robot_name}right_leg_j0_base"/>
    <child link="${robot_name}right_hip_roll"/>
    <origin rpy=" 0.000000 0 0.000000" xyz="0 0 0"/>
    <axis xyz="0 0 1"/>
    <dynamics damping="${right_leg_j0_damping}" friction="${right_leg_j0_friction}" />
    <limit effort="330.0" lower="-4.71239" upper="4.71239" velocity="1.0"/>
    <traits spring_k="2.5"   />
  </joint>

  <link name="${robot_name}right_hip_roll">
    <inertial>
      <mass value="2.33931"/>
      <inertia ixx="0.1" ixy="0.00" ixz="0.0" iyy="0.1" iyz="0.0" izz="0.1"/>
    </inertial>
    <visual>
      <geometry>
        <mesh filename="package://r2_description/meshes/r2_legs/r2cl_ext_bone3.dae"/>
      </geometry>
      <origin rpy="0 0 0" xyz="0.0 0.0 0.0"/>
    </visual>
    <collision>
      <geometry>
        <mesh filename="package://r2_description/meshes/r2_legs/r2cl_ext_bone3.dae"/>
      </geometry>
      <origin rpy="0 0 0" xyz="0.0 0.0 0.0"/>
    </collision>
  </link>

  <joint name="${robot_name}right_leg/joint1" type="revolute">
    <parent link="${robot_name}right_hip_roll"/>
    <child link="${robot_name}right_hip_pitch"/>
    <origin rpy="-1.570796  -0.2617994 0.0000000" xyz="0.050629765 -0.0022860 0.103498576" />
    <axis xyz="0 0 1"/>
    <dynamics damping="${right_leg_j1_damping}" friction="${right_leg_j1_friction}" />
    <limit effort="330.0" lower="-1.483" upper="1.27" velocity="1.0"/>
    <traits spring_k="2.5"   />
  </joint>

  <link name="${robot_name}right_hip_pitch">
    <inertial>
      <mass value="4.78221"/>
      <inertia ixx="0.1" ixy="0.00" ixz="0.0" iyy="0.1" iyz="0.0" izz="0.1"/>
    </inertial>
    <visual>
      <geometry>
        <mesh filename="package://r2_description/meshes/r2_legs/r2cl_ext_bone1.dae"/>
      </geometry>
      <origin rpy="0 0 0" xyz="0 0 0"/>
    </visual>
    <collision>
      <geometry>
        <mesh filename="package://r2_description/meshes/r2_legs/r2cl_ext_bone1.dae"/>
      </geometry>
      <origin rpy="0 0 0" xyz="0 0 0"/>
    </collision>
  </link>

  <joint name="${robot_name}right_leg/joint2" type="revolute">
    <parent link="${robot_name}right_hip_pitch"/>
    <child link="${robot_name}right_upper_leg"/>
    <origin rpy="-1.570796 0.0 -1.570796" xyz="0.200 -0.050 0.004"/>
    <axis xyz="0 0 1"/>
    <dynamics damping="${right_leg_j2_damping}" friction="${right_leg_j2_friction}" />
    <limit effort="330.0" lower="-4.71239" upper="4.71239" velocity="1.0"/>
    <traits spring_k="2.5"   />
  </joint>

  <link name="${robot_name}right_upper_leg">
    <inertial>
      <mass value="3.73407"/>
      <inertia ixx="0.1" ixy="0.00" ixz="0.0" iyy="0.1" iyz="0.0" izz="0.1"/>
    </inertial>
    <visual>
      <geometry>
        <mesh filename="package://r2_description/meshes/r2_legs/r2cl_ext_bone2.dae"/>
      </geometry>
      <origin rpy="0 0 0" xyz="0 0 0"/>
    </visual>
    <collision>
      <geometry>
        <mesh filename="package://r2_description/meshes/r2_legs/r2cl_ext_bone2.dae"/>
      </geometry>
      <origin rpy="0 0 0" xyz="0 0 0.0"/>
    </collision>
  </link>

  <joint name="${robot_name}right_leg/joint3" type="revolute">
    <parent link="${robot_name}right_upper_leg"/>
    <child link="${robot_name}right_knee"/>
    <origin rpy="0.0 -1.570796 3.14159" xyz="-0.00200 -0.050  0.157"/>
    <axis xyz="0 0 1"/>
    <dynamics damping="${right_leg_j3_damping}" friction="${right_leg_j3_friction}" />
    <limit effort="330.0" lower="-0.0872664" upper="2.6703515" velocity="1.0"/>
    <traits spring_k="2.5"   />
  </joint>

  <link name="${robot_name}right_knee">
    <inertial>
      <mass value="4.78221"/>
      <inertia ixx="0.1" ixy="0.00" ixz="0.0" iyy="0.1" iyz="0.0" izz="0.1"/>
    </inertial>
    <visual>
      <geometry>
        <mesh filename="package://r2_description/meshes/r2_legs/r2cl_ext_bone1.dae"/>
      </geometry>
      <origin rpy="0 0 0" xyz="0 0 0"/>
    </visual>
    <collision>
      <geometry>
        <mesh filename="package://r2_description/meshes/r2_legs/r2cl_ext_bone1.dae"/>
      </geometry>
      <material name="gold"/>
      <origin rpy="0 0 0" xyz="0 0 0"/>
    </collision>
  </link>

  <joint name="${robot_name}right_leg/joint4" type="revolute">
    <parent link="${robot_name}right_knee"/>
    <child link="${robot_name}right_lower_leg"/>
    <origin rpy="0 1.570796 0" xyz="0.200 -0.050 0.004"/>
    <axis xyz="0 0 1"/>
    <dynamics damping="${right_leg_j4_damping}" friction="${right_leg_j4_friction}" />
    <limit effort="330.0" lower="-4.71239" upper="4.71239" velocity="1.0"/>
    <traits spring_k="2.5"   />
  </joint>

  <link name="${robot_name}right_lower_leg">
    <inertial>
      <mass value="3.73407"/>
      <inertia ixx="0.1" ixy="0.00" ixz="0.0" iyy="0.1" iyz="0.0" izz="0.1"/>
    </inertial>
    <visual>
      <geometry>
        <mesh filename="package://r2_description/meshes/r2_legs/r2cl_ext_bone2.dae"/>
      </geometry>
      <origin rpy="0 0 0" xyz="0 0 0"/>
    </visual>
    <collision>
      <geometry>
        <mesh filename="package://r2_description/meshes/r2_legs/r2cl_ext_bone2.dae"/>
      </geometry>
      <origin rpy="0 0 0" xyz="0 0 0.0"/>
    </collision>
  </link>

  <joint name="${robot_name}right_leg/joint5" type="revolute">
    <parent link="${robot_name}right_lower_leg"/>
    <child link="${robot_name}right_ankle_pitch"/>
    <origin rpy="0.0 -1.570796 3.14159" xyz="-0.002 -0.050 0.157"/>
    <axis xyz="0 0 1"/>
    <dynamics damping="${right_leg_j5_damping}" friction="${right_leg_j5_friction}" />
    <limit effort="330.0" lower="-0.0872664" upper="2.6703515" velocity="1.0"/>
    <traits spring_k="2.5"   />
  </joint>

  <link name="${robot_name}right_ankle_pitch">
    <inertial>
      <mass value="4.78221"/>
      <inertia ixx="0.1" ixy="0.00" ixz="0.0" iyy="0.1" iyz="0.0" izz="0.1"/>
    </inertial>
    <visual>
      <geometry>
        <mesh filename="package://r2_description/meshes/r2_legs/r2cl_ext_bone1.dae"/>
      </geometry>
      <origin rpy="0 0 0" xyz="0 0 0"/>
    </visual>
    <collision>
      <geometry>
        <mesh filename="package://r2_description/meshes/r2_legs/r2cl_ext_bone1.dae"/>
      </geometry>
      <origin rpy="0 0 0" xyz="0 0 0"/>
    </collision>
  </link>

  <joint name="${robot_name}right_leg/joint6" type="revolute">
    <parent link="${robot_name}right_ankle_pitch"/>
    <child link="${robot_name}right_ankle_roll"/>
    <origin rpy="3.14159 -1.570796 0 " xyz="0.199643 -0.0508 0.00325"/>
    <axis xyz="0 0 1"/>
    <dynamics damping="${right_leg_j6_damping}" friction="${right_leg_j6_friction}" />
    <limit effort="330.0" lower="-4.71239" upper="4.71239" velocity="1.0"/>
    <traits spring_k="2.5"   />
  </joint>

  <link name="${robot_name}right_ankle_roll">
    <inertial>
      <mass value="1.50471"/>
      <inertia ixx="0.1" ixy="0.00" ixz="0.0" iyy="0.1" iyz="0.0" izz="0.1"/>
    </inertial>
    <visual>
      <geometry>
        <cylinder length=".06" radius=".066"/>
      </geometry>
      <material name="dirty_white"/>
      <origin rpy="0 0 0" xyz="0 0 0.025"/>
    </visual>
    <collision>
      <geometry>
        <cylinder length=".06" radius=".066"/>
      </geometry>
      <material name="gold"/>
      <origin rpy="0 0 0" xyz="0 0 0.025"/>
    </collision>
  </link>

</robot>
