<?xml version="1.0"?>
<robot>

  <property name="neck_j0_damping" value= "1.0" />
  <property name="neck_j0_friction" value= "0.0" />
  <property name="neck_j1_damping" value= "1.0" />
  <property name="neck_j1_friction" value= "0.0" />
  <property name="neck_j2_damping" value= "1.0" />
  <property name="neck_j2_friction" value= "0.0" />

  <property name="effort_limit" value= "10000.0" />
  <property name="velocity_limit" value= "1000.0" />

  <joint name="${robot_name}neck/joint0" type="revolute">
    <parent link="${robot_name}waist_center"/>
    <child link="${robot_name}neck_base"/>
    <origin rpy=" -1.570796 -0.0 0.0 " xyz=" 0.08636 0.0 -0.6142228 "/>
    <dynamics damping="${neck_j0_damping}" friction="${neck_j0_friction}"/>
    <axis xyz="0 0 1"/>
    <limit effort="${effort_limit}" lower="-0.7" upper="0.175" velocity="${velocity_limit}"/>
  </joint>

  <link name="${robot_name}neck_base">
    <visual>
      <geometry>
         <mesh filename="package://r2_description/meshes/Neck_Lower.dae"/>
      </geometry>
      <origin rpy="-1.57 1.57 0" xyz="0.0 0.0 0.0"/>
    </visual>
    <inertial>
      <mass value=".1"/>
      <inertia ixx=".0010" ixy="0.0" ixz="0.0" iyy=".0010" iyz="0.0" izz=".0010"/>
    </inertial>
    <collision>
      <geometry>
         <mesh filename="package://r2_description/meshes/Neck_Lower.dae"/>
      </geometry>
      <origin rpy="-1.57 1.57 0" xyz="0.0 0.0 0.0"/>
    </collision>
  </link>

  <joint name="${robot_name}neck/joint1" type="revolute">
    <parent link="${robot_name}neck_base"/>
    <child link="${robot_name}neck_lower_pitch"/>
    <origin rpy=" -1.570796 -0.0 0.0 " xyz=" -0.0762 -0.0 0.0 "/>
    <dynamics damping="${neck_j1_damping}" friction="${neck_j1_friction}"/>
    <axis xyz="0 0 1"/>
    <limit effort="${effort_limit}" lower="-1.22" upper="1.22" velocity="${velocity_limit}"/>
  </joint>

  <link name="${robot_name}neck_lower_pitch">
   <visual>
      <geometry>
         <mesh filename="package://r2_description/meshes/Neck_Upper.dae"/>
      </geometry>
      <origin rpy="0 0 1.57" xyz="0.075 0.0 0.0"/>
    </visual>
    <inertial>
      <mass value=".1"/>
      <inertia ixx=".0010" ixy="0.0" ixz="0.0" iyy=".0010" iyz="0.0" izz=".0010"/>
    </inertial>
    <collision>
      <geometry>
         <mesh filename="package://r2_description/meshes/Neck_Upper.dae"/>
      </geometry>
      <origin rpy="0 0 1.57" xyz="0.075 0.0 0.0"/>
    </collision>
  </link>

  <joint name="${robot_name}neck/joint2" type="revolute">
    <parent link="${robot_name}neck_lower_pitch"/>
    <child link="${robot_name}neck_roll"/>
    <origin rpy=" 1.570796 -0.0 0.0 " xyz=" 0.0508 0.0 0.1777619 "/>
    <dynamics damping="${neck_j2_damping}" friction="${neck_j2_friction}"/>
    <axis xyz="0 0 1"/>
    <limit effort="${effort_limit}" lower="-0.7" upper="0.175" velocity="${velocity_limit}"/>
  </joint>

  <link name="${robot_name}neck_roll">
    <visual>
      <geometry>
         <mesh filename="package://r2_description/meshes/Head.dae"/>
      </geometry>
      <origin rpy="0 1.57 0" xyz="-0.0 0.07 0.0"/>
    </visual>
    <collision>
      <geometry>
         <mesh filename="package://r2_description/meshes/Head.dae"/>
      </geometry>
      <origin rpy="0 1.57 0" xyz="-0.0 0.07 0.0"/>
    </collision>
    <inertial>
      <mass value=".1"/>
      <inertia ixx=".0010" ixy="0.0" ixz="0.0" iyy=".0010" iyz="0.0" izz=".0010"/>
    </inertial>
  </link>

  <joint name="${robot_name}fixed/neck_roll/neck_upper_pitch" type="fixed">
    <parent link="${robot_name}neck_roll"/>
    <child link="${robot_name}neck_upper_pitch"/>
    <origin rpy=" 1.570796 -0.0 0.0 " xyz=" 0.0 0.0 0.0 "/>
  </joint>

  <link name="${robot_name}neck_upper_pitch">
    <inertial>
      <mass value=".1"/>
      <inertia ixx=".0010" ixy="0.0" ixz="0.0" iyy=".0010" iyz="0.0" izz=".0010"/>
    </inertial>
  </link>

  <joint name="${robot_name}fixed/neck_upper_pitch/asus_frame" type="fixed">
    <parent link="${robot_name}neck_upper_pitch"/>
    <child link="${robot_name}asus_frame"/>
     <origin rpy="1.50 0.0 1.57 " xyz="0.12 -0.015 -0.14 "/>
<!-- OK    <origin rpy="1.45 0 1.57 " xyz="0.11 -0.040 -0.15 "/>  -->
<!-- ORIGINAL     <origin rpy="1.57 0 1.57 " xyz="0.066675 -0.0508 -0.116205 "/>  -->
  </joint>

  <joint name="${robot_name}fixed/neck_upper_pitch/simulated_asus_camera_frame" type="fixed">
    <parent link="${robot_name}neck_upper_pitch"/>
    <child link="${robot_name}simulated_asus_camera_frame"/>
    <dynamics damping="1.0" />
    <origin rpy="3.14 0 0" xyz="0.12 -0.015 -0.14 "/>
<!--     <origin rpy="0 0 0" xyz="0.12 -0.015 -0.14 "/> -->
  </joint>

  <joint name="${robot_name}fixed/neck_upper_pitch/simulated_asus_depth_frame" type="fixed">
    <parent link="${robot_name}neck_upper_pitch"/>
    <child link="${robot_name}simulated_asus_depth_frame"/>
    <dynamics damping="1.0" />
    <origin rpy="1.57 0 1.57" xyz="0.12 -0.015 -0.14 "/>
<!--     <origin rpy="0 0 0" xyz="0.12 -0.015 -0.14 "/> -->
  </joint>


  <joint name="${robot_name}fixed/neck_upper_pitch/vision_center_frame" type="fixed">
    <parent link="${robot_name}neck_upper_pitch"/>
    <child link="${robot_name}vision_center_frame"/>
    <dynamics damping="1.0" />
    <origin rpy="1.57 -1.57 1.57" xyz=" 0.066675 0.0 -0.116205 "/>
  </joint>

  <!-- actual asus -->
  <link name="${robot_name}asus_frame">
    <inertial>
      <mass value=".01"/>
      <inertia ixx=".0010" ixy="0.0" ixz="0.0" iyy=".0010" iyz="0.0" izz=".0010"/>
    </inertial>
  </link>

  <joint name="${robot_name}fixed/asus_frame/openni_depth_frame" type="fixed">
    <parent link="${robot_name}asus_frame"/>
    <child link="${robot_name}openni_depth_frame"/>
    <origin rpy="1.57 -1.57 0 " xyz="0 0 0 "/>
  </joint>

 <!-- asus default -->
 <link name="${robot_name}openni_depth_frame">
    <inertial>
      <mass value=".01"/>
      <inertia ixx=".0010" ixy="0.0" ixz="0.0" iyy=".0010" iyz="0.0" izz=".0010"/>
    </inertial>
  </link>

 <!-- simulated asus -->
 <link name="${robot_name}simulated_asus_camera_frame">
    <inertial>
      <mass value=".01"/>
      <inertia ixx=".0010" ixy="0.0" ixz="0.0" iyy=".0010" iyz="0.0" izz=".0010"/>
    </inertial>
  </link>

  <!-- simulated asus -->
 <link name="${robot_name}simulated_asus_depth_frame">
    <inertial>
      <mass value=".01"/>
      <inertia ixx=".0010" ixy="0.0" ixz="0.0" iyy=".0010" iyz="0.0" izz=".0010"/>
    </inertial>
  </link>

  <!--visions -->
  <link name="${robot_name}vision_center_frame">
    <inertial>
      <mass value=".1"/>
      <inertia ixx=".0010" ixy="0.0" ixz="0.0" iyy=".0010" iyz="0.0" izz=".0010"/>
    </inertial>
  </link>

  <joint name="${robot_name}fixed/vision_center_frame/left_camera_frame" type="fixed">
    <parent link="${robot_name}vision_center_frame"/>
    <child link="${robot_name}left_camera_frame"/>
    <dynamics damping="1.0" />
    <origin rpy="0 0 1.57" xyz="0.0087 0.04887 0.01789"/>
  </joint>

  <joint name="${robot_name}fixed/vision_center_frame/right_camera_frame" type="fixed">
    <parent link="${robot_name}vision_center_frame"/>
    <child link="${robot_name}right_camera_frame"/>
    <dynamics damping="1.0" />
    <origin rpy="0 0 1.57" xyz="0.0087 -0.04887 0.01789"/>
  </joint>

  <link name="${robot_name}left_camera_frame">
    <inertial>
      <mass value=".1"/>
      <inertia ixx=".0010" ixy="0.0" ixz="0.0" iyy=".0010" iyz="0.0" izz=".0010"/>
    </inertial>
  </link>

  <joint name="${robot_name}fixed/left_camera_frame/left_camera_optical_frame" type="fixed">
    <parent link="${robot_name}left_camera_frame"/>
    <child link="${robot_name}left_camera_optical_frame"/>
    <dynamics damping="1.0" />
    <origin rpy="-1.57 -1.57 0" xyz="0 0 0"/>
  </joint>

  <link name="${robot_name}left_camera_optical_frame">
    <inertial>
      <mass value=".1"/>
      <inertia ixx=".0010" ixy="0.0" ixz="0.0" iyy=".0010" iyz="0.0" izz=".0010"/>
    </inertial>
  </link>

  <link name="${robot_name}right_camera_frame">
    <inertial>
      <mass value=".1"/>
      <inertia ixx=".0010" ixy="0.0" ixz="0.0" iyy=".0010" iyz="0.0" izz=".0010"/>
    </inertial>
  </link>

  <joint name="${robot_name}fixed/right_camera_frame/right_camera_optical_frame" type="fixed">
    <parent link="${robot_name}right_camera_frame"/>
    <child link="${robot_name}right_camera_optical_frame"/>
    <dynamics damping="1.0" />
    <origin rpy="-1.57 -1.57 0" xyz="0 0 0"/>
  </joint>

  <link name="${robot_name}right_camera_optical_frame">
    <inertial>
      <mass value=".1"/>
      <inertia ixx=".0010" ixy="0.0" ixz="0.0" iyy=".0010" iyz="0.0" izz=".0010"/>
    </inertial>
  </link>

</robot>
